throw 用于手动抛出异常。 作为程序员可以在任意位置手动抛出异常。
throws 用于在方法上标识要暴露的异常。 抛出的异常交由调用者处理。

两者区别：
throw 用在方法内，后面跟上要抛出的异常类对象。
throws  修饰在方法上，告诉调用者此方法可能会抛出异常，后面跟上可能要抛出的异常类名。
                
Exception 异常是所有异常的父类异常


#### example1

```java

import  java.util.Scanner ;
import  java.util.InputMismatchException ;

public class ExceptionDemo2 {
    public static void main(String [] args){
        Bar bar = new Bar() ;       
        try {
            bar.enter(15) ;
        } catch(IllegalArgumentException e){
            System.out.println("错误信息：" + e.getMessage() )；
        }            
        System.out.println("end") ;                                
    }
}

class Bar{
    public void enter(int age) throws IllegalArgumentException {
        if(age < 18){
            //  受查异常（必须捕获）
            throw new IllegalArgumentException("年龄不合格") ;                    
        }else{
            System.out.println(“欢迎光临”)；                
        }        
    }
}


```


#### example2

```java

import  java.util.Scanner ;
import  java.util.InputMismatchException ;

public class ExceptionDemo2 {
    public static void main(String [] args){
        Bar bar = new Bar() ;       
        try {
			bar.enter(15) ;
        } catch(IllegalArgumentException e){
            System.out.println("错误信息：" + e.getMessage() )；
        }            
        System.out.println("end") ;                                
    }
}

class Bar{
    public void enter(int age) throws Exception {
        if(age < 18){
            //  受查异常（必须捕获）
            throw new Exception("年龄不合格") ;                    
        }else{
            System.out.println(“欢迎光临”)；                
        }        
    }
}

```


try {} 语句块中方的是要检测的 java 代码，可能有会抛出异常，也可能会正常执行。

catch（异常类型）{} 块是当 java 运行时系统接收到 try 块中所抛出异常对象时，会寻找能处理
这一异常 catch 块来进行处理（可以有多个 catch 块）。

finally {} 不管系统有没有抛出异常都会去执行，一般用来释放资源。除了在之前执行了 System.exit(0)
   
Exception 异常是所有异常的父类，可以接收所有所抛出的子类对象。


#### example3

```java
import java.util.Scanner ; 

public class ExceptionDemo1
{
    public static void main(String [] args){
        System.out.println("请输入一个数字：") ;
        Scanner input = new Scanner(System.in) ;        
        int number = input.nextInt() ;
        int res = 10/number ;
        System.out.println("结果为：" + res ) ;        
    }
}

以上是所写程序，下面是演示：

root@ansible:~/java/exception# java ExceptionDemo1
please input a number: 
1
The result is: 10

发现结果是正确的，没有任何错误。

但是如果输入一个字符，或者其他非整数的数就会报错
`
root@ansible:~/java/exception# java ExceptionDemo1
please input a number: 
a
Exception in thread "main" java.util.InputMismatchException
	at java.util.Scanner.throwFor(Scanner.java:864)
	at java.util.Scanner.next(Scanner.java:1485)
	at java.util.Scanner.nextInt(Scanner.java:2117)
	at java.util.Scanner.nextInt(Scanner.java:2076)
	at ExceptionDemo1.main(ExceptionDemo1.java:7)
	
	
-------------------------------------------------------------------------------

import java.util.Scanner ; 
import java.util.InputMismatchException ;
import java.lang.ArithmeticException ;

public class ExceptionDemo1 {
    public static void main(String[] args){
        System.out.println("请输入一个数字：") ;
        Scanner input = new Scanner(System.in) ;
        int res = 0 ;
        try {
            int number = input.nextInt() ; 
            int res = 10/number ;                
        } catch(InputMismatchException e) {
            System.out.println(e.getMessage()) ;
            e.printStackTrace() ;
        } catch(ArithmeticException e) {
            System.out.println(e.getMessage()) ;
            e.printStackTrace() ;
        } catch(Exception e){                        
            System.out.println(e.getMessage() ) ;       
        } finally {
            //  释放资源，比如关闭打开的文件，删除一些临时文件等
            System.out.println("结果为：" + res) ; 
        }                       
    }
    
    public void testTryFinally(String name){
        try {
            System.out.println( name.length() ) ;
        } finally {
            System.out.println("end") ;                
        }            
    }
}

运行如下：
root@ansible:~/java/exception/InputMismatchException# java ExceptionDemo1
请输入一个数：
a
null
java.util.InputMismatchException
	at java.util.Scanner.throwFor(Scanner.java:864)
	at java.util.Scanner.next(Scanner.java:1485)
	at java.util.Scanner.nextInt(Scanner.java:2117)
	at java.util.Scanner.nextInt(Scanner.java:2076)
	at ExceptionDemo1.main(ExceptionDemo1.java:10)
结果为：0

如果把当中 e.printStackTrace() 去掉，输出结果就为：
root@ansible:~/java/exception/InputMismatchException# java ExceptionDemo1
请输入一个数：
a
null
结果为：0

e.getMessage() 的值为null，这个nulll就代表这报错所输出的信息。

```


#### 医生给工作者看病

```java
import java.util.Random;

public class ExceptionTest {
    public static void main(String [] args){
        Worker worker = new Worker();
        Doctor doctor = new Doctor();
    
        try {
            worker.work();                
        } catch(SickException e) {
            doctor.cure(worker) ; 
            if (worker.getStatus().equals("健康") ) {
                System.out.println("恭喜你可以恢复了") ;                        
            } else {
                System.out.println("sorry，尽力了") ;
            }              
        } finally {
            System.out.println("欢迎下次来本院就诊") ;                
        }
    }
}

class Worker {
    private String status ;
    public void setStatus(String status){
        this.status = status ;
    }
    
    public String getStatus(){
        return status ;        
    }
    
    public void work() throws SickException {
        Random random = new Random() ; 
        int rad = random.nextInt(3) + 1 ;
        if(rad == 1){
            //  抛出一个自定义异常对象
            throw new SickException("我有病") ;                  
        } else {
            System.out.println("身体健康，不用治疗") ;                
        }
    }
}



//  此处表示继承 Exception 这个父类
class SickException extends Exception {
    private String message ;
    public SickException(String message) {
        this.message = message ;         
    }
    public String getMessage(){
        return message ;        
    }
}

class Doctor {
    public void cure(Worker worker){
        Random random = new Random() ; 
        int rad = random.nextInt(2) + 1 ; 
        if (rad == 1) {                       
            worker.setStatus("健康") ;                
        } else {
            worker.setStatus("死亡") ;                
        }
    }
}

```


#### 异常的概念和处理机制

什么是异常？
        所谓异常是指在程序运行的过程中发生的一些不正常事件。（如：除0溢出，数组下标越界，所要读取的文件不存在）。
        
异常导致的后果？
        Java 程序的执行过程中如出现异常事件，可以生成一个异常类对象，该异常对象封装了异常事件的信息，并将其被提交给Java 运行时系统，这个过程
称为抛出异常，不处理的话会直接导致程序直接中断。

如何防止程序中断？
        设计良好地程序应该在程序异常发生时提供处理这些异常的方法，使得程序不会因为异常的放生而阻断或产生不可预见的结果。
        

异常类型                            包括                                                  来源                                      处理
受查异常                        Exception及其子类                               由代码控制能力之外的          必须要处理，否则通不过编译
checkedException        （不包括 RuntimeException及其子类      因素导致的运行时错误

非受查异常                     Error 和 RuntimeException 及其子类     RuntimeException一般        可以不用处理
uncheckedException                                                                 代表编程错误


Java 的异常是通过两种机制来处理的
        捕获： try-catch-finally
        抛出： throw， throwss
        
        捕获异常
        
        try         监控区域，执行可能产生异常的代码
        
        catch     捕获，处理异常
        
        finally     善后处理，无论是否发生异常，代码总能执行
        
        throw     手动抛出异常
        
        throws    声明方法可能要抛出的异常



#### 自定义一个异常类

```java

public class ExceptionDemo3 {
    public static void main(String [] args){
        Bar bar = new Bar();
        try{
            bar.enter(15);
        }catch(AgeLessThanEighteenException e){
            System.out.println("错误信息: " + e.getMessage());
        }
        System.out.println("end");
    }
}

class AgeLessThanEighteenException extends Exception {
    private String message;
    public AgeLessThanEighteenException(String message){
        this.message = message;
    }
    public String getMessage(){
        return this.message;
    }
}

class Bar{
    public void enter(int age) throws AgeLessThanEighteenException {
        if(age < 18){
            throw new AgeLessThanEighteenException("年龄不合格");
        }else{
            System.out.println("欢迎光临");
        }
    }
}

```
